<?xml version="1.0" ?>
<!-- =================================================================================== -->
<!-- |    This document was autogenerated by xacro from ModelGenerator/ihmc_robotics/robots/hrp2.urdf.xacro | -->
<!-- |    EDITING THIS FILE BY HAND IS NOT RECOMMENDED                                 | -->
<!-- =================================================================================== -->
<robot name="HRP2" xmlns:xacro="http://www.ros.org/wiki/xacro">
  <link name="ROOT"/>
  <link name="RightLeg6">
  <inertial>
    <mass value="6.537500e-01"/>
    <origin rpy="0 0 0" xyz="8.270830e-03 -1.333010e-03 -2.418000e-03"/>
    <inertia ixx="2.777300e-04" ixy="-5.260000e-06" ixz="1.354000e-05" iyy="7.896600e-04" iyz="-3.590000e-06" izz="8.603900e-04"/>
  </inertial>
</link>
  <link name="RightLeg5">
    <inertial>
      <mass value="1.747620e+00"/>
      <origin rpy="0 0 0" xyz="1.798781e-02 -2.291638e-02 1.616098e-01"/>
      <inertia ixx="2.232685e-02" ixy="-9.393000e-05" ixz="-2.247760e-03" iyy="2.250598e-02" iyz="-7.452700e-04" izz="4.554430e-03"/>
    </inertial>
  </link>
  <link name="RightLeg4">
    <inertial>
      <mass value="2.076320e+00"/>
      <origin rpy="0 0 0" xyz="3.459460e-03 -7.794217e-02 1.483160e-01"/>
      <inertia ixx="2.619757e-02" ixy="-3.954000e-05" ixz="5.735100e-04" iyy="2.492350e-02" iyz="6.700700e-04" izz="3.764390e-03"/>
    </inertial>
  </link>
  <link name="RightLeg3">
    <inertial>
      <mass value="8.055300e-01"/>
      <origin rpy="0 0 0" xyz="-3.982600e-04 -2.612872e-02 -2.921560e-03"/>
      <inertia ixx="1.266830e-03" ixy="1.211000e-05" ixz="1.640000e-06" iyy="5.065600e-04" iyz="6.938000e-05" izz="1.320210e-03"/>
    </inertial>
  </link>
  <link name="RightLeg2">
    <inertial>
      <mass value="1.235480e+00"/>
      <origin rpy="0 0 0" xyz="-1.070336e-02 4.607160e-03 6.744546e-02"/>
      <inertia ixx="3.046890e-03" ixy="-1.558000e-05" ixz="-5.507700e-04" iyy="3.753050e-03" iyz="2.250000e-05" izz="1.538740e-03"/>
    </inertial>
  </link>
  <link name="RightLeg1">
    <inertial>
      <mass value="1.502949e+01"/>
      <origin rpy="0 0 0" xyz="-1.435142e-02 6.000012e-02 2.230769e-01"/>
      <inertia ixx="1.610262e-01" ixy="-2.600000e-07" ixz="7.069600e-04" iyy="9.528000e-02" iyz="-1.900000e-07" izz="1.919138e-01"/>
    </inertial>
  </link>
  <link name="LeftLeg1">
    <inertial>
      <mass value="1.235480e+00"/>
      <origin rpy="0 0 0" xyz="-1.070336e-02 -4.607160e-03 6.744546e-02"/>
      <inertia ixx="3.046890e-03" ixy="1.558000e-05" ixz="-5.507700e-04" iyy="3.753050e-03" iyz="-2.250000e-05" izz="1.538740e-03"/>
    </inertial>
  </link>
  <link name="LeftLeg2">
    <inertial>
      <mass value="8.055300e-01"/>
      <origin rpy="0 0 0" xyz="-3.982600e-04 2.612872e-02 -2.921560e-03"/>
      <inertia ixx="1.266830e-03" ixy="-1.211000e-05" ixz="1.640000e-06" iyy="5.065600e-04" iyz="-6.938000e-05" izz="1.320210e-03"/>
    </inertial>
  </link>
  <link name="LeftLeg3">
    <inertial>
      <mass value="2.076320e+00"/>
      <origin rpy="0 0 0" xyz="3.459460e-03 7.794217e-02 -1.516840e-01"/>
      <inertia ixx="2.619757e-02" ixy="3.954000e-05" ixz="5.735100e-04" iyy="2.492350e-02" iyz="-6.700700e-04" izz="3.764390e-03"/>
    </inertial>
  </link>
  <link name="LeftLeg4">
    <inertial>
      <mass value="1.747620e+00"/>
      <origin rpy="0 0 0" xyz="1.798781e-02 5.791638e-02 -1.383902e-01"/>
      <inertia ixx="2.232685e-02" ixy="9.393000e-05" ixz="-2.247760e-03" iyy="2.250598e-02" iyz="7.452700e-04" izz="4.554430e-03"/>
    </inertial>
  </link>
  <link name="LeftLeg5">
    <inertial>
      <mass value="6.537500e-01"/>
      <origin rpy="0 0 0" xyz="8.270830e-03 1.333010e-03 -2.418000e-03"/>
      <inertia ixx="2.777300e-04" ixy="5.260000e-06" ixz="1.354000e-05" iyy="7.896600e-04" iyz="3.590000e-06" izz="8.603900e-04"/>
    </inertial>
  </link>
  <link name="LeftLeg6">
    <inertial>
      <mass value="1.638770e+00"/>
      <origin rpy="0 0 0" xyz="-6.641900e-04 4.689220e-03 -6.538130e-02"/>
      <inertia ixx="4.000760e-03" ixy="-9.983000e-05" ixz="7.929500e-04" iyy="6.876110e-03" iyz="1.854100e-04" izz="7.115160e-03"/>
    </inertial>
  </link>
  <link name="Waist1">
    <inertial>
      <mass value="7.863692e-01"/>
      <origin rpy="0 0 0" xyz="-1.580159e-02 5.295440e-03 -2.519634e-02"/>
      <inertia ixx="1.816170e-03" ixy="-7.322000e-05" ixz="-2.773100e-04" iyy="1.850790e-03" iyz="-1.074900e-04" izz="2.332070e-03"/>
    </inertial>
  </link>
  <link name="Waist2">
    <inertial>
      <mass value="1.152457e+01"/>
      <origin rpy="0 0 0" xyz="-2.904963e-02 7.164110e-03 1.210246e-01"/>
      <inertia ixx="1.604757e-01" ixy="-1.359320e-03" ixz="-4.144930e-03" iyy="1.368458e-01" iyz="3.880350e-03" izz="1.816685e-01"/>
    </inertial>
  </link>
  <link name="Head1">
    <inertial>
      <mass value="3.747665e-01"/>
      <origin rpy="0 0 0" xyz="-8.753300e-04 4.261990e-03 -8.027470e-03"/>
      <inertia ixx="3.994500e-04" ixy="-9.900000e-07" ixz="2.260000e-06" iyy="2.255800e-04" iyz="-1.181000e-05" izz="3.624600e-04"/>
    </inertial>
  </link>
  <link name="Head2">
    <inertial>
      <mass value="9.933547e-01"/>
      <origin rpy="0 0 0" xyz="1.298846e-02 8.605000e-05 1.087606e-01"/>
      <inertia ixx="6.291190e-03" ixy="-2.165000e-05" ixz="6.933000e-04" iyy="5.468950e-03" iyz="-6.372000e-05" izz="5.906820e-03"/>
    </inertial>
  </link>
  <link name="RightArm1">
    <inertial>
      <mass value="8.100757e-01"/>
      <origin rpy="0 0 0" xyz="-9.894480e-03 4.645260e-02 -1.531600e-04"/>
      <inertia ixx="2.211150e-03" ixy="-3.042400e-04" ixz="1.470000e-06" iyy="1.841890e-03" iyz="4.667000e-05" izz="3.447720e-03"/>
    </inertial>
  </link>
  <link name="RightArm2">
    <inertial>
      <mass value="1.034480e+00"/>
      <origin rpy="0 0 0" xyz="-1.056459e-02 -1.204295e-02 -9.481560e-03"/>
      <inertia ixx="1.220980e-03" ixy="2.811900e-04" ixz="9.407000e-05" iyy="1.722160e-03" iyz="1.204100e-04" izz="1.613190e-03"/>
    </inertial>
  </link>
  <link name="RightArm3">
    <inertial>
      <mass value="1.599290e+00"/>
      <origin rpy="0 0 0" xyz="-5.430720e-03 -4.797970e-03 -1.668716e-01"/>
      <inertia ixx="9.730490e-03" ixy="-5.133000e-05" ixz="-1.991900e-04" iyy="9.703720e-03" iyz="1.374700e-04" izz="1.353310e-03"/>
    </inertial>
  </link>
  <link name="RightArm4">
    <inertial>
      <mass value="7.772499e-01"/>
      <origin rpy="0 0 0" xyz="-9.270000e-06 -1.616837e-02 -6.270155e-02"/>
      <inertia ixx="2.326680e-03" ixy="7.000000e-08" ixz="-3.100000e-07" iyy="2.124760e-03" iyz="1.509700e-04" izz="5.636300e-04"/>
    </inertial>
  </link>
  <link name="RightArm5">
    <inertial>
      <mass value="5.546686e-01"/>
      <origin rpy="0 0 0" xyz="-3.448630e-03 -3.617590e-03 4.149589e-02"/>
      <inertia ixx="1.321040e-03" ixy="1.646000e-05" ixz="4.660000e-05" iyy="1.199200e-03" iyz="-1.195900e-04" izz="3.171500e-04"/>
    </inertial>
  </link>
  <link name="RightArm6">
    <inertial>
      <mass value="5.738179e-01"/>
      <origin rpy="0 0 0" xyz="1.739000e-04 4.257500e-03 -5.829538e-02"/>
      <inertia ixx="9.384900e-04" ixy="-5.480000e-06" ixz="-8.170000e-06" iyy="1.025650e-03" iyz="-3.239000e-05" izz="4.595100e-04"/>
    </inertial>
  </link>
  <link name="LeftArm1">
    <inertial>
      <mass value="8.100757e-01"/>
      <origin rpy="0 0 0" xyz="-9.894480e-03 -4.645260e-02 -1.531600e-04"/>
      <inertia ixx="2.211150e-03" ixy="3.042400e-04" ixz="1.470000e-06" iyy="1.841890e-03" iyz="-4.667000e-05" izz="3.447720e-03"/>
    </inertial>
  </link>
  <link name="LeftArm2">
    <inertial>
      <mass value="1.034480e+00"/>
      <origin rpy="0 0 0" xyz="-1.056459e-02 1.204295e-02 -9.481560e-03"/>
      <inertia ixx="1.220980e-03" ixy="-2.811900e-04" ixz="9.407000e-05" iyy="1.722160e-03" iyz="-1.204100e-04" izz="1.613190e-03"/>
    </inertial>
  </link>
  <link name="LeftArm3">
    <inertial>
      <mass value="1.599290e+00"/>
      <origin rpy="0 0 0" xyz="-5.430720e-03 4.797970e-03 -1.668716e-01"/>
      <inertia ixx="9.730490e-03" ixy="5.133000e-05" ixz="-1.991900e-04" iyy="9.703720e-03" iyz="-1.374700e-04" izz="1.353310e-03"/>
    </inertial>
  </link>
  <link name="LeftArm4">
    <inertial>
      <mass value="7.772499e-01"/>
      <origin rpy="0 0 0" xyz="-9.270000e-06 1.616837e-02 -6.270155e-02"/>
      <inertia ixx="2.326680e-03" ixy="-7.000000e-08" ixz="-3.100000e-07" iyy="2.124760e-03" iyz="-1.509700e-04" izz="5.636300e-04"/>
    </inertial>
  </link>
  <link name="LeftArm5">
    <inertial>
      <mass value="5.546686e-01"/>
      <origin rpy="0 0 0" xyz="2.476940e-03 3.617590e-03 4.149589e-02"/>
      <inertia ixx="1.321030e-03" ixy="9.300000e-06" ixz="-3.617000e-05" iyy="1.198680e-03" iyz="1.195900e-04" izz="3.166400e-04"/>
    </inertial>
  </link>
  <link name="LeftArm6">
    <inertial>
      <mass value="5.738179e-01"/>
      <origin rpy="0 0 0" xyz="1.739000e-04 -4.257500e-03 -5.829538e-02"/>
      <inertia ixx="9.384900e-04" ixy="5.480000e-06" ixz="-8.170000e-06" iyy="1.025650e-03" iyz="3.239000e-05" izz="4.595100e-04"/>
    </inertial>
  </link>
  <joint name="Joint_1" type="revolute">
  <origin rpy="0 0 0" xyz="0 0 0"/>
  <axis xyz="1 0 0"/>
  <parent link="ROOT"/>
  <child link="RightLeg6"/>
  <dynamics damping="0.1" friction="0"/>
  <limit effort="106" lower="-0.663225" upper="0.663225" velocity="12"/>
  </joint>
  <joint name="Joint_2" type="revolute">
    <origin rpy="0 0 0" xyz="0 0 0"/>
    <axis xyz="0 1 0"/>
    <parent link="RightLeg6"/>
    <child link="RightLeg5"/>
    <dynamics damping="0.1" friction="0"/>
    <limit effort="106" lower="-0.663225" upper="0.663225" velocity="12"/>
  </joint>
  <joint name="Joint_3" type="revolute">
    <origin rpy="0 0 0" xyz="0 3.500000e-02 3.000000e-01"/>
    <axis xyz="0 1 0"/>
    <parent link="RightLeg5"/>
    <child link="RightLeg4"/>
    <dynamics damping="0.1" friction="0"/>
    <limit effort="106" lower="-0.663225" upper="0.663225" velocity="12"/>
  </joint>
  <joint name="Joint_4" type="revolute">
    <origin rpy="0 0 0" xyz="0 0 3.000000e-01"/>
    <axis xyz="0 1 0"/>
    <parent link="RightLeg4"/>
    <child link="RightLeg3"/>
    <dynamics damping="0.1" friction="0"/>
    <limit effort="106" lower="-0.663225" upper="0.663225" velocity="12"/>
  </joint>
  <joint name="Joint_5" type="revolute">
    <origin rpy="0 0 0" xyz="0 0 0"/>
    <axis xyz="1 0 0"/>
    <parent link="RightLeg3"/>
    <child link="RightLeg2"/>
    <dynamics damping="0.1" friction="0"/>
    <limit effort="106" lower="-0.663225" upper="0.663225" velocity="12"/>
  </joint>
  <joint name="Joint_6" type="revolute">
    <origin rpy="0 0 0" xyz="0 0 0"/>
    <axis xyz="0 0 1"/>
    <parent link="RightLeg2"/>
    <child link="RightLeg1"/>
    <dynamics damping="0.1" friction="0"/>
    <limit effort="106" lower="-0.663225" upper="0.663225" velocity="12"/>
  </joint>
  <joint name="Joint_7" type="revolute">
    <origin rpy="0 0 0" xyz="0 1.200000e-01 0"/>
    <axis xyz="0 0 1"/>
    <parent link="RightLeg1"/>
    <child link="LeftLeg1"/>
    <dynamics damping="0.1" friction="0"/>
    <limit effort="106" lower="-0.663225" upper="0.663225" velocity="12"/>
  </joint>
  <joint name="Joint_8" type="revolute">
    <origin rpy="0 0 0" xyz="0 0 0"/>
    <axis xyz="1 0 0"/>
    <parent link="LeftLeg1"/>
    <child link="LeftLeg2"/>
    <dynamics damping="0.1" friction="0"/>
    <limit effort="106" lower="-0.663225" upper="0.663225" velocity="12"/>
  </joint>
  <joint name="Joint_9" type="revolute">
    <origin rpy="0 0 0" xyz="0 0 0"/>
    <axis xyz="0 1 0"/>
    <parent link="LeftLeg2"/>
    <child link="LeftLeg3"/>
    <dynamics damping="0.1" friction="0"/>
    <limit effort="106" lower="-0.663225" upper="0.663225" velocity="12"/>
  </joint>
  <joint name="Joint_10" type="revolute">
    <origin rpy="0 0 0" xyz="0 0 -3.000000e-01"/>
    <axis xyz="0 1 0"/>
    <parent link="LeftLeg3"/>
    <child link="LeftLeg4"/>
    <dynamics damping="0.1" friction="0"/>
    <limit effort="106" lower="-0.663225" upper="0.663225" velocity="12"/>
  </joint>
  <joint name="Joint_11" type="revolute">
    <origin rpy="0 0 0" xyz="0 3.500000e-02 -3.000000e-01"/>
    <axis xyz="0 1 0"/>
    <parent link="LeftLeg4"/>
    <child link="LeftLeg5"/>
    <dynamics damping="0.1" friction="0"/>
    <limit effort="106" lower="-0.663225" upper="0.663225" velocity="12"/>
  </joint>
  <joint name="Joint_12" type="revolute">
    <origin rpy="0 0 0" xyz="0 0 0"/>
    <axis xyz="1 0 0"/>
    <parent link="LeftLeg5"/>
    <child link="LeftLeg6"/>
    <dynamics damping="0.1" friction="0"/>
    <limit effort="106" lower="-0.663225" upper="0.663225" velocity="12"/>
  </joint>
  <joint name="Joint_13" type="revolute">
    <origin rpy="0 0 0" xyz="3.200000e-02 6.000000e-02 3.507000e-01"/>
    <axis xyz="0 0 1"/>
    <parent link="RightLeg1"/>
    <child link="Waist1"/>
    <dynamics damping="0.1" friction="0"/>
    <limit effort="106" lower="-0.663225" upper="0.663225" velocity="12"/>
  </joint>
  <joint name="Joint_14" type="revolute">
    <origin rpy="0 0 0" xyz="0 0 0"/>
    <axis xyz="0 1 0"/>
    <parent link="Waist1"/>
    <child link="Waist2"/>
    <dynamics damping="0.1" friction="0"/>
    <limit effort="106" lower="-0.663225" upper="0.663225" velocity="12"/>
  </joint>
  <joint name="Joint_15" type="revolute">
    <origin rpy="0 0 0" xyz="-7.000000e-03 0 2.973000e-01"/>
    <axis xyz="0 0 1"/>
    <parent link="Waist2"/>
    <child link="Head1"/>
    <dynamics damping="0.1" friction="0"/>
    <limit effort="106" lower="-0.663225" upper="0.663225" velocity="12"/>
  </joint>
  <joint name="Joint_16" type="revolute">
    <origin rpy="0 0 0" xyz="0 0 2.700000e-02"/>
    <axis xyz="0 1 0"/>
    <parent link="Head1"/>
    <child link="Head2"/>
    <dynamics damping="0.1" friction="0"/>
    <limit effort="106" lower="-0.663225" upper="0.663225" velocity="12"/>
  </joint>
  <joint name="Joint_17" type="revolute">
    <origin rpy="0 0 0" xyz="8.000000e-03 -2.500000e-01 1.810000e-01"/>
    <axis xyz="0 1 0"/>
    <parent link="Waist2"/>
    <child link="RightArm1"/>
    <dynamics damping="0.1" friction="0"/>
    <limit effort="106" lower="-0.663225" upper="0.663225" velocity="12"/>
  </joint>
  <joint name="Joint_18" type="revolute">
    <origin rpy="0 0 0" xyz="0 0 0"/>
    <axis xyz="1 0 0"/>
    <parent link="RightArm1"/>
    <child link="RightArm2"/>
    <dynamics damping="0.1" friction="0"/>
    <limit effort="106" lower="-0.663225" upper="0.663225" velocity="12"/>
  </joint>
  <joint name="Joint_19" type="revolute">
    <origin rpy="0 0 0" xyz="0 0 0"/>
    <axis xyz="0 0 1"/>
    <parent link="RightArm2"/>
    <child link="RightArm3"/>
    <dynamics damping="0.1" friction="0"/>
    <limit effort="106" lower="-0.663225" upper="0.663225" velocity="12"/>
  </joint>
  <joint name="Joint_20" type="revolute">
    <origin rpy="0 0 0" xyz="0 0 -2.500000e-01"/>
    <axis xyz="0 1 0"/>
    <parent link="RightArm3"/>
    <child link="RightArm4"/>
    <dynamics damping="0.1" friction="0"/>
    <limit effort="106" lower="-0.663225" upper="0.663225" velocity="12"/>
  </joint>
  <joint name="Joint_21" type="revolute">
    <origin rpy="0 0 0" xyz="0 0 -2.500000e-01"/>
    <axis xyz="0 0 1"/>
    <parent link="RightArm4"/>
    <child link="RightArm5"/>
    <dynamics damping="0.1" friction="0"/>
    <limit effort="106" lower="-0.663225" upper="0.663225" velocity="12"/>
  </joint>
  <joint name="Joint_22" type="revolute">
    <origin rpy="0 0 0" xyz="0 0 0"/>
    <axis xyz="0 1 0"/>
    <parent link="RightArm5"/>
    <child link="RightArm6"/>
    <dynamics damping="0.1" friction="0"/>
    <limit effort="106" lower="-0.663225" upper="0.663225" velocity="12"/>
  </joint>
  <joint name="Joint_23" type="revolute">
    <origin rpy="0 0 0" xyz="8.000000e-03 2.500000e-01 1.810000e-01"/>
    <axis xyz="0 1 0"/>
    <parent link="Waist2"/>
    <child link="LeftArm1"/>
    <dynamics damping="0.1" friction="0"/>
    <limit effort="106" lower="-0.663225" upper="0.663225" velocity="12"/>
  </joint>
  <joint name="Joint_24" type="revolute">
    <origin rpy="0 0 0" xyz="0 0 0"/>
    <axis xyz="1 0 0"/>
    <parent link="LeftArm1"/>
    <child link="LeftArm2"/>
    <dynamics damping="0.1" friction="0"/>
    <limit effort="106" lower="-0.663225" upper="0.663225" velocity="12"/>
  </joint>
  <joint name="Joint_25" type="revolute">
    <origin rpy="0 0 0" xyz="0 0 0"/>
    <axis xyz="0 0 1"/>
    <parent link="LeftArm2"/>
    <child link="LeftArm3"/>
    <dynamics damping="0.1" friction="0"/>
    <limit effort="106" lower="-0.663225" upper="0.663225" velocity="12"/>
  </joint>
  <joint name="Joint_26" type="revolute">
    <origin rpy="0 0 0" xyz="0 0 -2.500000e-01"/>
    <axis xyz="0 1 0"/>
    <parent link="LeftArm3"/>
    <child link="LeftArm4"/>
    <dynamics damping="0.1" friction="0"/>
    <limit effort="106" lower="-0.663225" upper="0.663225" velocity="12"/>
  </joint>
  <joint name="Joint_27" type="revolute">
    <origin rpy="0 0 0" xyz="0 0 -2.500000e-01"/>
    <axis xyz="0 0 1"/>
    <parent link="LeftArm4"/>
    <child link="LeftArm5"/>
    <dynamics damping="0.1" friction="0"/>
    <limit effort="106" lower="-0.663225" upper="0.663225" velocity="12"/>
  </joint>
  <joint name="Joint_28" type="revolute">
    <origin rpy="0 0 0" xyz="0 0 0"/>
    <axis xyz="0 1 0"/>
    <parent link="LeftArm5"/>
    <child link="LeftArm6"/>
    <dynamics damping="0.1" friction="0"/>
    <limit effort="106" lower="-0.663225" upper="0.663225" velocity="12"/>
  </joint>
</robot>