<?xml version="1.0" ?>

<robot name="nao_inertial_python" FileName="/home/nao/Dropbox/PhD/qt_projects/OpenHRC_Geo/src/data/NAOTemplate.xml" DEFName="NAO_blue" DoF="24" RobotModel="NAO inertial">

<!-- ********** KINEMATIC PROPERTIES (JOINTS) ********** -->

	<joint name="Joint1" type="revolute">
	   <parent link="ROOT"/>
	   <child link="LLEG_link6"/>
	   <origin rpy="0.0 0.0 0.0" xyz="0.0 0.0 0.0"/>
	   <axis xyz="1 0 0"/>
	   <limit upper="0.769001" lower="-0.397880" effort="0.0" velocity="1.0"/>
	</joint>
	<joint name="Joint2" type="revolute">
	   <parent link="LLEG_link6"/>
	   <child link="LLEG_link5"/>
	   <origin rpy="0.0 0.0 0.0" xyz="0.0 0.0 0.0"/>
	   <axis xyz="0 1 0"/>
	   <limit upper="0.922747" lower="-1.189516" effort="0.0" velocity="1.0"/>
	</joint>
	<joint name="Joint3" type="revolute">
	   <parent link="LLEG_link5"/>
	   <child link="LLEG_link4"/>
	   <origin rpy="0.0 0.0 0.0" xyz="0.0 0.0 0.10290"/>
	   <axis xyz="0 1 0"/>
	   <limit upper="2.112528" lower="-0.092346" effort="0.0" velocity="1.0"/>
	</joint>
	<joint name="Joint4" type="revolute">
	   <parent link="LLEG_link4"/>
	   <child link="LLEG_link3"/>
	   <origin rpy="0.0 0.0 0.0" xyz="0.0 0.0 0.1"/>
	   <axis xyz="0 1 0"/>
	   <limit upper="0.484090" lower="-1.535889" effort="0.0" velocity="1.0"/>
	</joint>
	<joint name="Joint5" type="revolute">
	   <parent link="LLEG_link3"/>
	   <child link="LLEG_link2"/>
	   <origin rpy="0.0 0.0 0.0" xyz="0.0 0.0 0.0"/>
	   <axis xyz="1 0 0"/>
	   <limit upper="0.790477" lower="-0.379472" effort="0.0" velocity="1.0"/>
	</joint>
	<joint name="joint6" type="revolute">
	   <parent link="LLEG_link2"/>
	   <child link="LLEG_link1"/>
	   <origin rpy="0.0 0.0 0.0" xyz="0.0 0.0 0.0"/>
	   <axis xyz="0 0.707106781186547 -0.707106781186547"/>
	   <limit upper="0.740810" lower="-1.145303" effort="0.0" velocity="1.0"/>
	</joint>



	<joint name="Joint7" type="revolute">
	   <parent link="LLEG_link1"/>
	   <child link="LARM_link1"/>
	   <origin rpy="0.0 0.0 0.0" xyz="0 0.048 0.185"/>
	   <axis xyz="0 1 0"/>
	   <limit upper="2.0857" lower="-2.0857" effort="0.0" velocity="1.0"/>
	</joint>
	<joint name="Joint8" type="revolute">
	   <parent link="LARM_link1"/>
	   <child link="LARM_link2"/>
	   <origin rpy="0.0 0.0 0.0" xyz="0.0 0.0 0.0"/>
	   <axis xyz="0 0 1"/>
	   <limit upper="1.6494" lower="0.0087" effort="0.0" velocity="1.0"/>
	</joint>
	<joint name="Joint9" type="revolute">
	   <parent link="LARM_link2"/>
	   <child link="LARM_link3"/>
	   <origin rpy="0.0 0.0 0.0" xyz="0.105 0.015 0.0"/>
	   <axis xyz="1 0 0"/>
	   <limit upper="2.0857" lower="-2.0857" effort="0.0" velocity="1.0"/>
	</joint>
	<joint name="Joint10" type="revolute">
	   <parent link="LARM_link3"/>
	   <child link="LARM_link4"/>
	   <origin rpy="0.0 0.0 0.0" xyz="0.0 0.0 0.0"/>
	   <axis xyz="0 0 1"/>
	   <limit upper="-0.0087" lower="-1.5621" effort="0.0" velocity="1.0"/>
	</joint>
	<joint name="Joint11" type="revolute">
	   <parent link="LARM_link4"/>
	   <child link="LARM_link5"/>
	   <origin rpy="0.0 0.0 0.0" xyz="0.05595 0.0 0.0"/>
	   <axis xyz="1 0 0"/>
	   <limit upper="1.8238" lower="-1.8238" effort="0.0" velocity="1.0"/>
	</joint>


	
	<joint name="Joint12" type="revolute">
	   <parent link="LLEG_link1"/>
	   <child link="HEAD_link1"/>
	   <origin rpy="0.0 0.0 0.0" xyz="0.0 -0.05 0.2115"/>
	   <axis xyz="0 0 1"/>
	   <limit upper="2.0857" lower="-2.0857" effort="0.0" velocity="1.0"/>
	</joint>
	<joint name="Joint13" type="revolute">
	   <parent link="HEAD_link1"/>
	   <child link="HEAD_link2"/>
	   <origin rpy="0.0 0.0 0.0" xyz="0.0 0.0 0.0"/>
	   <axis xyz="0 1 0"/>
	   <limit upper="0.5149" lower="-0.6720" effort="0.0" velocity="1.0"/>
	</joint>



	<joint name="Joint14" type="revolute">
	   <parent link="LLEG_link1"/>
	   <child link="RARM_link1"/>
	   <origin rpy="0.0 0.0 0.0" xyz="0.0 -0.148 0.185"/>
	   <axis xyz="0 1 0"/>
	   <limit upper="2.0857" lower="-2.0857" effort="0.0" velocity="1.0"/>
	</joint>
	<joint name="Joint15" type="revolute">
	   <parent link="RARM_link1"/>
	   <child link="RARM_link2"/>
	   <origin rpy="0.0 0.0 0.0" xyz="0.0 0.0 0.0"/>
	   <axis xyz="0 0 1"/>
	   <limit upper="-0.0087" lower="-1.6494" effort="0.0" velocity="1.0"/>
	</joint>
	<joint name="Joint16" type="revolute">
	   <parent link="RARM_link2"/>
	   <child link="RARM_link3"/>
	   <origin rpy="0.0 0.0 0.0" xyz="0.105 -0.015 0.0"/>
	   <axis xyz="1 0 0"/>
	   <limit upper="2.0857" lower="-2.0857" effort="0.0" velocity="1.0"/>
	</joint>
	<joint name="Joint17" type="revolute">
	   <parent link="RARM_link3"/>
	   <child link="RARM_link4"/>
	   <origin rpy="0.0 0.0 0.0" xyz="0.0 0.0 0.0"/>
	   <axis xyz="0 0 1"/>
	   <limit upper="1.5621" lower="0.0087" effort="0.0" velocity="1.0"/>
	</joint>
	<joint name="Joint18" type="revolute">
	   <parent link="RARM_link4"/>
	   <child link="RARM_link5"/>
	   <origin rpy="0.0 0.0 0.0" xyz="0.05595 0.0 0.0"/>
	   <axis xyz="1 0 0"/>
	   <limit upper="1.8238" lower="-1.8238" effort="0.0" velocity="1.0"/>
	</joint>



	<joint name="Joint19" type="revolute">
	   <parent link="LLEG_link1"/>
	   <child link="RLEG_link1"/>
	   <origin rpy="0.0 0.0 0.0" xyz="0 -0.1 0.0"/>
	   <axis xyz="0 0.707106781186547 0.707106781186547"/>
	   <limit upper="0.740810" lower="-1.145303" effort="0.0" velocity="1.0"/>
	</joint>
	<joint name="Joint20" type="revolute">
	   <parent link="RLEG_link1"/>
	   <child link="RLEG_link2"/>
	   <origin rpy="0.0 0.0 0.0" xyz="0.0 0.0 0.0"/>
	   <axis xyz="1 0 0"/>
	   <limit upper="0.379472" lower="-0.790477" effort="0.0" velocity="1.0"/>
	</joint>
	<joint name="Joint21" type="revolute">
	   <parent link="RLEG_link2"/>
	   <child link="RLEG_link3"/>
	   <origin rpy="0.0 0.0 0.0" xyz="0.0 0.0 0.0"/>
	   <axis xyz="0 1 0"/>
	   <limit upper="0.484090" lower="-1.535889" effort="0.0" velocity="1.0"/>
	</joint>
	<joint name="Joint22" type="revolute">
	   <parent link="RLEG_link3"/>
	   <child link="RLEG_link4"/>
	   <origin rpy="0.0 0.0 0.0" xyz="0.0 0.0 -0.1"/>
	   <axis xyz="0 1 0"/>
	   <limit upper="2.120198" lower="-0.103083" effort="0.0" velocity="1.0"/>
	</joint>
	<joint name="Joint23" type="revolute">
	   <parent link="RLEG_link4"/>
	   <child link="RLEG_link5"/>
	   <origin rpy="0.0 0.0 0.0" xyz="0.0 0.0 -0.1029"/>
	   <axis xyz="0 1 0"/>
	   <limit upper="0.932056" lower="-1.186448" effort="0.0" velocity="1.0"/>
	</joint>
	<joint name="Joint24" type="revolute">
	   <parent link="RLEG_link5"/>
	   <child link="RLEG_link6"/>
	   <origin rpy="0.0 0.0 0.0" xyz="0.0 0.0 0.0"/>
	   <axis xyz="1 0 0"/>
	   <limit upper="0.397935" lower="-0.768992" effort="0.0" velocity="1.0"/>
	</joint>


<!-- ********** INERTIAL PROPERTIES (LINKS) ********** -->

	<link name="ROOT"/>
	<link name="LLEG_link6">
	   <inertial>
		<mass value="0.13416"/>
		<origin rpy="0.0 0.0 0.0" xyz="0.00045 0.00029 0.00685"/>
		<inertia ixx="3.8509781007e-5" ixy="-2.6340000403e-8" ixz="3.8619400584e-6"
			 iyy="7.4265262811e-5" iyz="1.8339999741e-8" izz="5.4865398852e-5"/>
	   </inertial>
	</link>
	<link name="LLEG_link5">
	   <inertial>
		<mass value="0.30142"/>
		<origin rpy="0.0 0.0 0.0" xyz="0.00453 0.00225 0.05354"/>
		<inertia ixx="1.1820796644e-3" ixy="6.63362000446e-7" ixz="3.6496971006e-5"
			 iyy="1.1286522495e-3" iyz="3.949522943e-5" izz="1.9322744629e-4"/>
	   </inertial>
	</link>	
	<link name="LLEG_link4">
	   <inertial>
		<mass value="0.38968"/>
		<origin rpy="0.0 0.0 0.0" xyz="0.00138 0.00221 0.04627"/>
		<inertia ixx="1.636719564e-3" ixy="9.2451000455e-7" ixz="8.5306681285e-5"
			 iyy="1.591072767e-3" iyz="3.8361598854e-5" izz="3.0374340713e-4"/>
	   </inertial>
	</link>
	<link name="LLEG_link3">
	   <inertial>
		<mass value="0.14053"/>
		<origin rpy="0.0 0.0 0.0" xyz="-0.01549 0.00029 -0.00515"/>
		<inertia ixx="2.7583539122e-5" ixy="-2.2329999183e-8" ixz="-4.0816398723e-6"
			 iyy="9.8270553281e-5" iyz="-4.1899999026e-9" izz="8.8099732238e-5"/>
	   </inertial>
	</link>
	<link name="LLEG_link2">
	   <inertial>
	    <mass value="0.06981"/>
		<origin rpy="0.0 0.0 0.0" xyz="-0.00781 -0.01114 0.02661"/>
		<inertia ixx="8.1502330431e-5" ixy="-4.9944901548e-6" ixz="1.2748169866e-5"
			 iyy="1.0132555326e-4" iyz="2.3454740585e-5" izz="6.2623628764e-5"/>
	   </inertial>
	</link>
	<link name="LLEG_link1">
	   <inertial>
		<mass value="1.0496"/>
		<origin rpy="0.0 0.0 0.0" xyz="-0.00413 -0.05 0.12842"/>
		<inertia ixx="5.0623407587e-3" ixy="1.4311580344e-5" ixz="1.5519082081e-4"
			 iyy="4.8801358789e-3" iyz="-2.7079340725e-5" izz="1.610300038e-3"/>
	   </inertial>
	</link>



	<link name="LARM_link1">
	   <inertial>
		<mass value="0.09304"/>
		<origin rpy="0.0 0.0 0.0" xyz="-0.00165 -0.02663 0.00014"/>
		<inertia ixx="8.4284300101e-5" ixy="-2.0280199351e-6" ixz="2.3380000158e-8"
	 		 iyy="1.4155610188e-5" iyz="-1.9719999855e-8" izz="8.6419488071e-5"/>
	   </inertial>
	</link>
	<link name="LARM_link2">
	   <inertial>
		<mass value="0.15777"/>
		<origin rpy="0.0 0.0 0.0" xyz="0.02455 0.00563 0.0033"/>
		<inertia ixx="9.3899929198e-5" ixy="-4.7144520067e-5" ixz="-2.6994710424e-5"
			 iyy="3.7151877768e-4" iyz="-2.4597700303e-6" izz="3.4190082806e-4"/>
	   </inertial>
	</link>
	<link name="LARM_link3">
	   <inertial>
		<mass value="0.06483"/>
		<origin rpy="0.0 0.0 0.0" xyz="-0.02744 0 -0.00014"/>
		<inertia ixx="5.5971499933e-6" ixy="4.299999042e-9" ixz="4.3189999133e-8"
			 iyy="7.5433119491e-5" iyz="-1.8400000412e-9" izz="7.6443393482e-5"/>
	   </inertial>
	</link>
	<link name="LARM_link4">
	   <inertial>
		<mass value="0.07761"/>
		<origin rpy="0.0 0.0 0.0" xyz="0.02556 0.00281 0.00076"/>
		<inertia ixx="2.5332199584e-5" ixy="-2.3427101041e-6" ixz="7.4589998178e-8"
			 iyy="8.91321979e-5" iyz="-2.6549999532e-8" izz="8.7287262431e-5"/>
	   </inertial>
	</link>	
	<link name="LARM_link5">
	   <inertial>
		<mass value="0.18533"/>
		<origin rpy="0.0 0.0 0.0" xyz="0.03434 -0.00088 0.00308"/>
		<inertia ixx="7.0549329394e-5" ixy="5.715990028e-6" ixz="-2.247437078e-5"
			 iyy="3.560623154e-4" iyz="3.1777099139e-6" izz="3.5191932693e-4"/>
	   </inertial>
	</link>	



	<link name="HEAD_link1">
	   <inertial>
		<mass value="0.07842"/>
		<origin rpy="0.0 0.0 0.0" xyz="-1e-5 0.0 -0.02742"/>
		<inertia ixx="7.4992953159e-5" ixy="1.5700000189e-9" ixz="-1.8339999741e-8"
			 iyy="7.5999952969e-5" iyz="-5.294999994e-8" izz="5.5337300182e-6"/>
	   </inertial>
	</link>
	<link name="HEAD_link2">
	   <inertial>
		<mass value="0.60533"/>
		<origin rpy="0.0 0.0 0.0" xyz="-0.00112 0.0 0.05258"/>
		<inertia ixx="2.63129523696e-3" ixy="8.788139894e-6" ixz="4.0984661609e-5"
			 iyy="2.4911249056e-3" iyz="-2.995792056e-5" izz="9.8573567811e-4"/>
	   </inertial>
	</link>



	<link name="RARM_link1">
	   <inertial>
		<mass value="0.09304"/>
		<origin rpy="0.0 0.0 0.0" xyz="-0.00165 0.02663 0.00014"/>
		<inertia ixx="8.4284300101e-5" ixy="2.0280199351e-6" ixz="2.3380000158e-8"
	 		 iyy="1.4155610188e-5" iyz="1.9719999855e-8" izz="8.6419488071e-5"/>
	   </inertial>
	</link>
	<link name="RARM_link2">
	   <inertial>
		<mass value="0.15777"/>
		<origin rpy="0.0 0.0 0.0" xyz="0.02455 -0.00563 0.0033"/>
		<inertia ixx="1.1012030882e-4" ixy="7.6691307186e-5" ixz="-2.6046069252e-5"
			 iyy="3.6757651833e-4" iyz="1.2098280422e-5" izz="3.5461771768e-4"/>
	   </inertial>
	</link>
	<link name="RARM_link3">
	   <inertial>
		<mass value="0.06483"/>
		<origin rpy="0.0 0.0 0.0" xyz="-0.02744 0 -0.00014"/>
		<inertia ixx="5.5971499933e-6" ixy="4.2099999042e-9" ixz="4.3189999133e-8"
	 		 iyy="7.5433119491e-5" iyz="-1.8400000412e-9" izz="7.6443393482e-5"/>
	   </inertial>
	</link>
	<link name="RARM_link4">
	   <inertial>
		<mass value="0.07761"/>
		<origin rpy="0.0 0.0 0.0" xyz="0.02556 -0.00281 0.00076"/>
		<inertia ixx="2.5390700102e-5" ixy="2.3324300855e-6" ixz="-6.0116997247e-7"
			 iyy="8.9220360678e-5" iyz="2.6940000453e-8" izz="8.7248430646e-5"/>
	   </inertial>
	</link>	
	<link name="RARM_link5">
	   <inertial>
		<mass value="0.18533"/>
		<origin rpy="0.0 0.0 0.0" xyz="0.03434 0.00088 0.00308"/>
		<inertia ixx="7.0549329394e-5" ixy="5.715990028e-6" ixz="-2.247437078e-5"
			 iyy="3.560623154e-4" iyz="3.1777099139e-6" izz="3.5191932693e-4"/>
	   </inertial>
	</link>









	<link name="RLEG_link1">
	   <inertial>
		<mass value="0.06981"/>
		<origin rpy="0.0 0.0 0.0" xyz="-0.00781 0.01114 0.02661"/>
		<inertia ixx="8.9971952548e-5" ixy="5.0021899369e-6" ixz="1.2735249584e-5"
			 iyy="1.0552610911e-4" iyz="-2.7700800274e-5" izz="6.6887238063e-5"/>
	   </inertial>
	</link>
	<link name="RLEG_link2">
	   <inertial>
		<mass value="0.14053"/>
		<origin rpy="0.0 0.0 0.0" xyz="-0.01549 -0.00029 -0.00515"/>
		<inertia ixx="2.7583539122e-5" ixy="-1.91900007e-8" ixz="-4.108219855e-6"
			 iyy="9.8269956652e-5" iyz="2.5099999856e-9" izz="8.8103319285e-5"/>
	   </inertial>
	</link>
	<link name="RLEG_link3">
	   <inertial>
		<mass value="0.38968"/>
		<origin rpy="0.0 0.0 0.0" xyz="0.00138 -0.00221 -0.05373"/>
		<inertia ixx="1.6374820843e-3" ixy="-8.3954000729e-7" ixz="8.5883009888e-5"
			 iyy="1.5922139864e-3" iyz="-3.9176258724e-5" izz="3.0397824594e-4"/>
	   </inertial>
	</link>
	<link name="RLEG_link4">
	   <inertial>
		<mass value="0.30142"/>
		<origin rpy="0.0 0.0 0.0" xyz="0.00453 -0.00225 -0.04936"/>
		<inertia ixx="1.1828296119e-3" ixy="-8.96500012e-7" ixz="2.7996900826e-5"
			 iyy="1.1282785563e-3" iyz="-3.8476038753e-5" izz="1.9145276747e-4"/>
	   </inertial>
	</link>	
	<link name="RLEG_link5">
	   <inertial>
		<mass value="0.13416"/>
		<origin rpy="0.0 0.0 0.0" xyz="0.00045 -0.00029 0.00685"/>
		<inertia ixx="3.8508129364e-5" ixy="6.4339999994e-8" ixz="3.8746597966e-6"
			 iyy="7.4310817581e-5" iyz="-4.5799999349e-9" izz="5.491311822e-5"/>
	   </inertial>
	</link>
	<link name="RLEG_link6">
	   <inertial>
		<mass value="0.17184"/>
		<origin rpy="0.0 0.0 0.0" xyz="0.02542 -0.0033 -0.03239"/>
		<inertia ixx="2.6930202148e-4" ixy="5.8750501921e-6" ixz="1.3913327712e-4"
			 iyy="6.4347387524e-4" iyz="-1.8849170374e-5" izz="5.2503478946e-4"/>
	   </inertial>
	</link>
</robot>
