<Robot FileName="/home/alvaropaz/Dropbox/PhD/qt_projects/OpenHRC_Geo/src/data/NAOTemplate.xml" DEFName="NAO_blue" DoF="6" NaoVersion="V5">

<!-- ********** KINEMATIC PROPERTIES (JOINTS) ********** -->

	<Joint name="Joint1" Type="Revolute">
	   <parent link="ROOT"/>
	   <child link="LLEG_link6"/>
	   <origin rpy="0.0 0.0 0.0" xyz="0.0 0.0 0.0"/>
	   <axis xyz="1 0 0"/>
	   <Limit Max="0.769001" Min="-0.397880"/>
	</Joint>
	<Joint name="Joint2" Type="Revolute">
	   <parent link="LLEG_link6"/>
	   <child link="LLEG_link5"/>
	   <origin rpy="0.0 0.0 0.0" xyz="0.0 0.0 0.0"/>
	   <axis xyz="0 1 0"/>
	   <Limit Max="0.922747" Min="-1.189516"/>
	</Joint>
	<Joint name="Joint3" Type="Revolute">
	   <parent link="LLEG_link5"/>
	   <child link="LLEG_link4"/>
	   <origin rpy="0.0 0.0 0.0" xyz="0.0 0.0 0.10290"/>
	   <axis xyz="0 1 0"/>
	   <Limit Max="2.112528" Min="-0.092346"/>
	</Joint>
	<Joint name="Joint4" Type="Revolute">
	   <parent link="LLEG_link4"/>
	   <child link="LLEG_link3"/>
	   <origin rpy="0.0 0.0 0.0" xyz="0.0 0.0 0.1"/>
	   <axis xyz="0 1 0"/>
	   <Limit Max="0.484090" Min="-1.535889"/>
	</Joint>
	<Joint name="Joint5" Type="Revolute">
	   <parent link="LLEG_link3"/>
	   <child link="LLEG_link2"/>
	   <origin rpy="0.0 0.0 0.0" xyz="0.0 0.0 0.0"/>
	   <axis xyz="1 0 0"/>
	   <Limit Max="0.790477" Min="-0.379472"/>
	</Joint>
	<Joint name="Joint6" Type="Revolute">
	   <parent link="LLEG_link2"/>
	   <child link="LLEG_link1"/>
	   <origin rpy="0.0 0.0 0.0" xyz="0.0 0.0 0.0"/>
	   <axis xyz="0 0.707106781186547 -0.707106781186547"/>
	   <Limit Max="0.740810" Min="-1.145303"/>
	</Joint>


<!-- ********** INERTIAL PROPERTIES (LINKS) ********** -->


	<link name="LLEG_link6">
	   <inertial>
		<mass value="0.13416"/>
		<origin rpy="0.0 0.0 0.0" xyz="0.00045, 0.00029, 0.00685"/>
		<inertia ixx="3.8509781007e-5" ixy="-2.6340000403e-8" ixz="3.8619400584e-6"
			 iyy="7.4265262811e-5" iyz="1.8339999741e-8" izz="5.4865398852e-5"/>
	   </inertial>
	</link>
	<link name="LLEG_link5">
	   <inertial>
		<mass value="0.30142"/>
		<origin rpy="0.0 0.0 0.0" xyz="0.00453, 0.00225, 0.05354"/>
		<inertia ixx="1.1820796644e-3" ixy="6.63362000446e-7" ixz="3.6496971006e-5"
			 iyy="1.1286522495e-3" iyz="3.949522943e-5" izz="1.9322744629e-4"/>
	   </inertial>
	</link>	
	<link name="LLEG_link4">
	   <inertial>
		<mass value="0.38968"/>
		<origin rpy="0.0 0.0 0.0" xyz="0.00138, 0.00221, 0.04627"/>
		<inertia ixx="1.636719564e-3" ixy="9.2451000455e-7" ixz="8.5306681285e-5"
			 iyy="1.591072767e-3" iyz="3.8361598854e-5" izz="3.0374340713e-4"/>
	   </inertial>
	</link>
	<link name="LLEG_link3">
	   <inertial>
		<mass value="0.14053"/>
		<origin rpy="0.0 0.0 0.0" xyz="-0.01549, 0.00029, -0.00515"/>
		<inertia ixx="2.7583539122e-5" ixy="-2.2329999183e-8" ixz="-4.0816398723e-6"
			 iyy="9.8270553281e-5" iyz="-4.1899999026e-9" izz="8.8099732238e-5"/>
	   </inertial>
	</link>
	<link name="LLEG_link2">
	   <inertial>
	    <mass value="0.06981"/>
		<origin rpy="0.0 0.0 0.0" xyz="-0.00781, -0.01114, 0.02661"/>
		<inertia ixx="8.1502330431e-5" ixy="-4.9944901548e-6" ixz="1.2748169866e-5"
			 iyy="1.0132555326e-4" iyz="2.3454740585e-5" izz="6.2623628764e-5"/>
	   </inertial>
	</link>
	<link name="LLEG_link1">
	   <inertial>
		<mass value="1.0496"/>
		<origin rpy="0.0 0.0 0.0" xyz="-0.00413, -0.05, 0.12842"/>
		<inertia ixx="5.0623407587e-3" ixy="1.4311580344e-5" ixz="1.5519082081e-4"
			 iyy="4.8801358789e-3" iyz="-2.7079340725e-5" izz="1.610300038e-3"/>
	   </inertial>
	</link>
</Robot>