<?xml version="1.0"?>
<robot name="kelly" dof="2" planar="true" author="kordaz">


<!-- ********** KINEMATIC PROPERTIES (JOINTS) ********** -->
	<joint name="Joint1" type="revolute">
	   <parent link="ROOT"/>
	   <child link="link1"/>
	   <origin rpy="0.0 0.0 0.0" xyz="0.0 0.0 0.0"/>
	   <axis xyz="1 0 0"/>
	   <limit effort="3" velocity="1.178465545" upper="100" lower="-100"/>
	</joint>

	<joint name="Joint2" type="revolute">
	   <parent link="link1"/>
	   <child link="link2"/>
	   <origin rpy="0.0 0.0 0.0" xyz="0.0 0.0 -0.450"/>
	   <axis xyz="1 0 0"/>
           <limit effort="3" velocity="1.178465545" upper="150" lower="-150"/>
	</joint>


<!-- ********** INERTIAL PROPERTIES (LINKS) ********** -->

	<link name="ROOT">
           <inertial>
		<mass value="0"/>
		<origin rpy="0.0 0.0 0.0" xyz="0.0 0.0 0.0"/>
		<inertia ixx="0.0" ixy="0.0" ixz="0.0"
			 iyy="0.0" iyz="0.0" izz="0.0"/>
           </inertial>
	</link>

	<link name="link1">
        <inertial>
            <mass value="5.902"/>
		<origin rpy="0.0 0.0 0.0" xyz="0.0 0.0 -0.091"/>
		<inertia ixx="1.26" ixy="0" ixz="0"
			 iyy="1.26" iyz="0" izz="1.26"/>
	   </inertial>
       <visual>
        <origin xyz="0 0 0" rpy="0 0 0"/>
        <material name="red">
            <color rgba="1.0 0.0 0.0 0.91"/>
        </material>
        <geometry>
            <sphere radius="0.03"/>
        </geometry>
       </visual>
       <visual>
        <origin xyz="0 0 -0.091" rpy="0 0 0"/>
        <material name="blue">
            <color rgba="0.0 0.0 1.0 0.91"/>
        </material>
        <geometry>
            <sphere radius="0.035"/>
        </geometry>
       </visual>
       <visual>
        <origin xyz="0 0 -0.225" rpy="0 0 0"/>
        <material name="red">
            <color rgba="1.0 0.5 0.0 0.1"/>
        </material>
        <geometry>
            <cylinder length="0.450" radius="0.02"/>
        </geometry>
    </visual>

	</link>

	<link name="link2">
	   <inertial>
		<mass value="3.880"/>
		<origin rpy="0.0 0.0 0.0" xyz="0.0 0.0 -0.048"/>
		<inertia ixx="0.093" ixy="0" ixz="0"
			 iyy="0.093" iyz="0" izz="0.093"/>
	   </inertial>
       <visual>
        <origin xyz="0 0 0" rpy="0 0 0"/>
        <material name="green">
            <color rgba="0.0 1.0 0.0 0.91"/>
        </material>
        <geometry>
            <sphere radius="0.03"/>
        </geometry>
       </visual>
       <visual>
        <origin xyz="0 0 -0.225" rpy="0 0 0"/>
        <material name="green">
            <color rgba="0.0 1.0 0.0 0.91"/>
        </material>
        <geometry>
            <cylinder length="0.450" radius="0.02"/>
        </geometry>
    </visual>
	</link>
</robot>

